Workbook

Sheet Dashboard
B2: WORLD CUP 2026 — PREDICTION TOOL
B3: Input team data → engine predicts every match • 48 nations • Jun 11 – Jul 19, 2026
B5: HOW THIS WORKBOOK WORKS
B6: 1. | C6: Fill in the BLUE cells across tabs 2-6 with the data you have for each team.
B7: 2. | C7: GREY cells are locked formulas. They update automatically — don't edit them.
B8: 3. | C8: Default placeholder values are pre-filled so the engine runs out of the box.
B9: 4. | C9: Open the Predictions tab to see all 72 group-stage forecasts updating live.
B10: 5. | C10: Override any specific prediction in the rightmost column if you disagree with the model.
B12: COLOR KEY
B13: 1.23 | C13: BLUE on light blue | D13: Your inputs — edit these
B14: =A1+B1 -> 0 | C14: BLACK on grey | D14: Same-sheet locked formulas
B15: =Form_L20!I5 -> 0.47826087 | C15: GREEN on grey | D15: Cross-sheet link (Predictions tab)
B17: WORKBOOK MAP
B18: 📋 All 48 teams (reference) | E18: Reference
B19: 📊 Recent Form (Last 20) | E19: INPUTS
B20: 👥 Squad & Tournament DNA | E20: INPUTS
B21: ⚽ Tactical Mapping | E21: INPUTS
B22: 🎯 Goal Source Analysis | E22: INPUTS
B23: ⏱ Goal Timing (15-min) | E23: INPUTS
B24: 🏆 PREDICTION ENGINE | E24: OUTPUT — all 72 matches
B26: KEY DATES
B27: June 12, 2026 | D27: ⚠ SQUAD REVIEW ALERT — Integrate final 26-man squad lists (FIFA deadline May 30)
B28: June 11, 2026 | D28: Tournament opens: Mexico vs South Africa, Estadio Azteca
B29: June 12, 2026 | D29: Canada vs Bosnia & Herzegovina; USA vs Paraguay
B30: June 26-27, 2026 | D30: Group stage ends; Round of 32 begins
B31: July 19, 2026 | D31: Final — MetLife Stadium, East Rutherford NJ

Sheet Teams_Master
A1: TEAMS MASTER LIST
A2: All 48 nations — reference data (locked)
A3: 🟦 BLUE cells = your inputs (edit these) ◾ GREY cells = locked formulas (don't edit)
A4: # | B4: Team | C4: Confederation | D4: Group | E4: Pot | F4: FIFA Rank (Apr '26) | G4: WC Apps | H4: Best Finish
A5: 1 | B5: Mexico | C5: CONCACAF | D5: A | E5: 1 | F5: 15 | G5: 17 | H5: QF (1970, 1986)
A6: 2 | B6: South Korea | C6: AFC | D6: A | E6: 2 | F6: 22 | G6: 11 | H6: 4th (2002)
A7: 3 | B7: South Africa | C7: CAF | D7: A | E7: 3 | F7: 56 | G7: 4 | H7: Group (Host 2010)
A8: 4 | B8: Czechia | C8: UEFA | D8: A | E8: 4 | F8: 40 | G8: 10 | H8: Runner-up (1934, 1962)
A9: 5 | B9: Canada | C9: CONCACAF | D9: B | E9: 1 | F9: 30 | G9: 3 | H9: Group (1986, 2022)
A10: 6 | B10: Switzerland | C10: UEFA | D10: B | E10: 2 | F10: 19 | G10: 12 | H10: QF (1934, 1938, 1954)
A11: 7 | B11: Qatar | C11: AFC | D11: B | E11: 3 | F11: 53 | G11: 2 | H11: Group (2022)
A12: 8 | B12: Bosnia and Herzegovina | C12: UEFA | D12: B | E12: 4 | F12: 75 | G12: 2 | H12: Group (2014)
A13: 9 | B13: Brazil | C13: CONMEBOL | D13: C | E13: 1 | F13: 5 | G13: 23 | H13: Champion (1958-2002 x5)
A14: 10 | B14: Morocco | C14: CAF | D14: C | E14: 2 | F14: 14 | G14: 7 | H14: 4th (2022)
A15: 11 | B15: Scotland | C15: UEFA | D15: C | E15: 3 | F15: 39 | G15: 9 | H15: Group
A16: 12 | B16: Haiti | C16: CONCACAF | D16: C | E16: 4 | F16: 83 | G16: 2 | H16: Group (1974)
... A52: 48 | B52: Ghana | C52: CAF | D52: L | E52: 4 | F52: 76 | G52: 5 | H52: QF (2010)

Sheet Form_L20
A1: RECENT FORM — Last 20 Official Matches
A2: 🟦 Edit BLUE cells. Win %, Goal Diff, and Avg per Game recalculate automatically.
A3: 🟦 BLUE cells = your inputs (edit these) ◾ GREY cells = locked formulas (don't edit)
A4: # | B4: Team | C4: Confed. | D4: Group | E4: Played | F4: Wins | G4: Draws | H4: Losses | I4: Win % | J4: GF | K4: GA | L4: Goal Diff | M4: Avg GF/G | N4: Avg GA/G | O4: Clean Sheets | P4: Failed to Score | Q4: SoS × | R4: PPG/3
A5: 1 | B5: Mexico | C5: CONCACAF | D5: A | E5: 23 | F5: 11 | G5: 8 | H5: 4 | I5: =IFERROR(F5/E5,0) -> 0.47826087 | J5: 29 | K5: 17 | L5: =J5-K5 -> 12 | M5: =IFERROR(J5/E5,0) -> 1.2608696 | N5: =IFERROR(K5/E5,0) -> 0.73913043 | O5: 6 | P5: Copa/NL/GoldCup base + 10 Tier-1 friendlies (draw-heavy: D Japan/SK/Ecuador/Uruguay/Portugal/Belgium; L Colombia 0-4 & Paraguay; W Ghana/Australia). Friendly slump visible. | Q5: 0.84 | R5: =IFERROR((3*F5+G5)/(3*E5),0) -> 0.5942029
A6: 2 | B6: South Korea | C6: AFC | D6: A | E6: 15 | F6: 10 | G6: 2 | H6: 3 | I6: =IFERROR(F6/E6,0) -> 0.66666667 | J6: 33 | K6: 18 | L6: =J6-K6 -> 15 | M6: =IFERROR(J6/E6,0) -> 2.2 | N6: =IFERROR(K6/E6,0) -> 1.2 | O6: 5 | P6: AFC quals (7-1-2) + Tier-1 friendlies: W USA 2-0, D Mexico 2-2, L Brazil 0-5, W Paraguay, W Ghana. Brazil thrashing = reality check. | Q6: 0.83 | R6: =IFERROR((3*F6+G6)/(3*E6),0) -> 0.71111111
A7: 3 | B7: South Africa | C7: CAF | D7: A | E7: 10 | F7: 5 | G7: 3 | H7: 2 | I7: =IFERROR(F7/E7,0) -> 0.5 | J7: 15 | K7: 9 | L7: =J7-K7 -> 6 | M7: =IFERROR(J7/E7,0) -> 1.5 | N7: =IFERROR(K7/E7,0) -> 0.9 | O7: 3 | P7: 6 | Q7: 0.72 | R7: =IFERROR((3*F7+G7)/(3*E7),0) -> 0.6
A8: 4 | B8: Czechia | C8: UEFA | D8: A | E8: 10 | F8: 5 | G8: 3 | H8: 2 | I8: =IFERROR(F8/E8,0) -> 0.5 | J8: 22 | K8: 12 | L8: =J8-K8 -> 10 | M8: =IFERROR(J8/E8,0) -> 2.2 | N8: =IFERROR(K8/E8,0) -> 1.2 | O8: 4 | P8: 5 | Q8: 0.96 | R8: =IFERROR((3*F8+G8)/(3*E8),0) -> 0.6
A9: 5 | B9: Canada | C9: CONCACAF | D9: B | E9: 15 | F9: 6 | G9: 5 | H9: 4 | I9: =IFERROR(F9/E9,0) -> 0.4 | J9: 18 | K9: 15 | L9: =J9-K9 -> 3 | M9: =IFERROR(J9/E9,0) -> 1.2 | N9: =IFERROR(K9/E9,0) -> 1 | O9: 4 | P9: CONCACAF/NL base + Copa America 2024 SEMIFINALIST (lost Argentina SF). SoS lifted for proven strong-opposition run. | Q9: 0.82 | R9: =IFERROR((3*F9+G9)/(3*E9),0) -> 0.51111111
A10: 6 | B10: Switzerland | C10: UEFA | D10: B | E10: 6 | F10: 4 | G10: 2 | H10: 0 | I10: =IFERROR(F10/E10,0) -> 0.66666667 | J10: 14 | K10: 2 | L10: =J10-K10 -> 12 | M10: =IFERROR(J10/E10,0) -> 2.3333333 | N10: =IFERROR(K10/E10,0) -> 0.33333333 | O10: 6 | P10: 4 | Q10: 0.96 | R10: =IFERROR((3*F10+G10)/(3*E10),0) -> 0.77777778
A11: 7 | B11: Qatar | C11: AFC | D11: B | E11: 12 | F11: 4 | G11: 5 | H11: 3 | I11: =IFERROR(F11/E11,0) -> 0.33333333 | J11: 16 | K11: 22 | L11: =J11-K11 -> -6 | M11: =IFERROR(J11/E11,0) -> 1.3333333 | N11: =IFERROR(K11/E11,0) -> 1.8333333 | O11: 3 | P11: 6 | Q11: 0.72 | R11: =IFERROR((3*F11+G11)/(3*E11),0) -> 0.47222222
A12: 8 | B12: Bosnia and Herzegovina | C12: UEFA | D12: B | E12: 10 | F12: 5 | G12: 4 | H12: 1 | I12: =IFERROR(F12/E12,0) -> 0.5 | J12: 19 | K12: 9 | L12: =J12-K12 -> 10 | M12: =IFERROR(J12/E12,0) -> 1.9 | N12: =IFERROR(K12/E12,0) -> 0.9 | O12: 4 | P12: 5 | Q12: 0.96 | R12: =IFERROR((3*F12+G12)/(3*E12),0) -> 0.63333333
A13: 9 | B13: Brazil | C13: CONMEBOL | D13: C | E13: 20 | F13: 13 | G13: 4 | H13: 3 | I13: =IFERROR(F13/E13,0) -> 0.65 | J13: 38 | K13: 15 | L13: =J13-K13 -> 23 | M13: =IFERROR(J13/E13,0) -> 1.9 | N13: =IFERROR(K13/E13,0) -> 0.75 | O13: 9 | P13: 2 | Q13: 1 | R13: =IFERROR((3*F13+G13)/(3*E13),0) -> 0.71666667
A14: 10 | B14: Morocco | C14: CAF | D14: C | E14: 20 | F14: 13 | G14: 4 | H14: 3 | I14: =IFERROR(F14/E14,0) -> 0.65 | J14: 33 | K14: 14 | L14: =J14-K14 -> 19 | M14: =IFERROR(J14/E14,0) -> 1.65 | N14: =IFERROR(K14/E14,0) -> 0.7 | O14: 11 | P14: 3 | Q14: 1 | R14: =IFERROR((3*F14+G14)/(3*E14),0) -> 0.71666667
A15: 11 | B15: Scotland | C15: UEFA | D15: C | E15: 6 | F15: 4 | G15: 1 | H15: 1 | I15: =IFERROR(F15/E15,0) -> 0.66666667 | J15: 13 | K15: 7 | L15: =J15-K15 -> 6 | M15: =IFERROR(J15/E15,0) -> 2.1666667 | N15: =IFERROR(K15/E15,0) -> 1.1666667 | O15: 4 | P15: 5 | Q15: 0.96 | R15: =IFERROR((3*F15+G15)/(3*E15),0) -> 0.72222222
A16: 12 | B16: Haiti | C16: CONCACAF | D16: C | E16: 6 | F16: 3 | G16: 2 | H16: 1 | I16: =IFERROR(F16/E16,0) -> 0.5 | J16: 9 | K16: 6 | L16: =J16-K16 -> 3 | M16: =IFERROR(J16/E16,0) -> 1.5 | N16: =IFERROR(K16/E16,0) -> 1 | O16: 2 | P16: 8 | Q16: 0.72 | R16: =IFERROR((3*F16+G16)/(3*E16),0) -> 0.61111111
A17: 13 | B17: United States | C17: CONCACAF | D17: D | E17: 21 | F17: 10 | G17: 2 | H17: 9 | I17: =IFERROR(F17/E17,0) -> 0.47619048 | J17: 34 | K17: 29 | L17: =J17-K17 -> 5 | M17: =IFERROR(J17/E17,0) -> 1.6190476 | N17: =IFERROR(K17/E17,0) -> 1.3809524 | O17: 5 | P17: Copa/NL/GoldCup base + 10 Tier-1 friendlies (W Japan/Australia/Paraguay/Uruguay/Senegal; L S.Korea/Belgium/Portugal/Germany; D Ecuador). Honest mid-tier. | Q17: 0.85 | R17: =IFERROR((3*F17+G17)/(3*E17),0) -> 0.50793651
A18: 14 | B18: Paraguay | C18: CONMEBOL | D18: D | E18: 21 | F18: 7 | G18: 7 | H18: 7 | I18: =IFERROR(F18/E18,0) -> 0.33333333 | J18: 17 | K18: 18 | L18: =J18-K18 -> -1 | M18: =IFERROR(J18/E18,0) -> 0.80952381 | N18: =IFERROR(K18/E18,0) -> 0.85714286 | O18: 4 | P18: CONMEBOL quals + Copa America 2024 REALITY CHECK: lost all 3 group games (vs Colombia, Brazil, Costa Rica). Weaker than qualifying implied. | Q18: 1.12 | R18: =IFERROR((3*F18+G18)/(3*E18),0) -> 0.44444444
A19: 15 | B19: Australia | C19: AFC | D19: D | E19: 10 | F19: 5 | G19: 4 | H19: 1 | I19: =IFERROR(F19/E19,0) -> 0.5 | J19: 17 | K19: 8 | L19: =J19-K19 -> 9 | M19: =IFERROR(J19/E19,0) -> 1.7 | N19: =IFERROR(K19/E19,0) -> 0.8 | O19: 4 | P19: 5 | Q19: 0.72 | R19: =IFERROR((3*F19+G19)/(3*E19),0) -> 0.63333333
A20: 16 | B20: Türkiye | C20: UEFA | D20: D | E20: 8 | F20: 6 | G20: 1 | H20: 1 | I20: =IFERROR(F20/E20,0) -> 0.75 | J20: 19 | K20: 12 | L20: =J20-K20 -> 7 | M20: =IFERROR(J20/E20,0) -> 2.375 | N20: =IFERROR(K20/E20,0) -> 1.5 | O20: 5 | P20: 4 | Q20: 0.96 | R20: =IFERROR((3*F20+G20)/(3*E20),0) -> 0.79166667
A21: 17 | B21: Germany | C21: UEFA | D21: E | E21: 20 | F21: 13 | G21: 4 | H21: 3 | I21: =IFERROR(F21/E21,0) -> 0.65 | J21: 40 | K21: 17 | L21: =J21-K21 -> 23 | M21: =IFERROR(J21/E21,0) -> 2 | N21: =IFERROR(K21/E21,0) -> 0.85 | O21: 9 | P21: 2 | Q21: 1 | R21: =IFERROR((3*F21+G21)/(3*E21),0) -> 0.71666667
A22: 18 | B22: Ecuador | C22: CONMEBOL | D22: E | E22: 18 | F22: 8 | G22: 8 | H22: 2 | I22: =IFERROR(F22/E22,0) -> 0.44444444 | J22: 14 | K22: 5 | L22: =J22-K22 -> 9 | M22: =IFERROR(J22/E22,0) -> 0.77777778 | N22: =IFERROR(K22/E22,0) -> 0.27777778 | O22: 4 | P22: 5 | Q22: 1.12 | R22: =IFERROR((3*F22+G22)/(3*E22),0) -> 0.59259259
A23: 19 | B23: Ivory Coast | C23: CAF | D23: E | E23: 10 | F23: 8 | G23: 2 | H23: 0 | I23: =IFERROR(F23/E23,0) -> 0.8 | J23: 25 | K23: 0 | L23: =J23-K23 -> 25 | M23: =IFERROR(J23/E23,0) -> 2.5 | N23: =IFERROR(K23/E23,0) -> 0 | O23: 4 | P23: 5 | Q23: 0.8 | R23: =IFERROR((3*F23+G23)/(3*E23),0) -> 0.86666667
A24: 20 | B24: Curaçao | C24: CONCACAF | D24: E | E24: 6 | F24: 3 | G24: 3 | H24: 0 | I24: =IFERROR(F24/E24,0) -> 0.5 | J24: 13 | K24: 3 | L24: =J24-K24 -> 10 | M24: =IFERROR(J24/E24,0) -> 2.1666667 | N24: =IFERROR(K24/E24,0) -> 0.5 | O24: 2 | P24: 8 | Q24: 0.72 | R24: =IFERROR((3*F24+G24)/(3*E24),0) -> 0.66666667
A25: 21 | B25: Netherlands | C25: UEFA | D25: F | E25: 20 | F25: 13 | G25: 5 | H25: 2 | I25: =IFERROR(F25/E25,0) -> 0.65 | J25: 41 | K25: 16 | L25: =J25-K25 -> 25 | M25: =IFERROR(J25/E25,0) -> 2.05 | N25: =IFERROR(K25/E25,0) -> 0.8 | O25: 10 | P25: 2 | Q25: 1 | R25: =IFERROR((3*F25+G25)/(3*E25),0) -> 0.73333333
A26: 22 | B26: Japan | C26: AFC | D26: F | E26: 16 | F26: 10 | G26: 4 | H26: 2 | I26: =IFERROR(F26/E26,0) -> 0.625 | J26: 41 | K26: 10 | L26: =J26-K26 -> 31 | M26: =IFERROR(J26/E26,0) -> 2.5625 | N26: =IFERROR(K26/E26,0) -> 0.625 | O26: 6 | P26: AFC quals (7-2-1, 30/3) + Tier-1 friendlies: W Germany 4-1, W Brazil 3-2, D Mexico, D Paraguay, W Ghana, L USA. SoS lifted: proved vs elite. | Q26: 0.84 | R26: =IFERROR((3*F26+G26)/(3*E26),0) -> 0.70833333
A27: 23 | B27: Tunisia | C27: CAF | D27: F | E27: 10 | F27: 9 | G27: 1 | H27: 0 | I27: =IFERROR(F27/E27,0) -> 0.9 | J27: 22 | K27: 0 | L27: =J27-K27 -> 22 | M27: =IFERROR(J27/E27,0) -> 2.2 | N27: =IFERROR(K27/E27,0) -> 0 | O27: 3 | P27: 6 | Q27: 0.72 | R27: =IFERROR((3*F27+G27)/(3*E27),0) -> 0.93333333
A28: 24 | B28: Sweden | C28: UEFA | D28: F | E28: 8 | F28: 2 | G28: 2 | H28: 4 | I28: =IFERROR(F28/E28,0) -> 0.25 | J28: 10 | K28: 15 | L28: =J28-K28 -> -5 | M28: =IFERROR(J28/E28,0) -> 1.25 | N28: =IFERROR(K28/E28,0) -> 1.875 | O28: 4 | P28: 5 | Q28: 0.96 | R28: =IFERROR((3*F28+G28)/(3*E28),0) -> 0.33333333
A29: 25 | B29: Belgium | C29: UEFA | D29: G | E29: 20 | F29: 12 | G29: 5 | H29: 3 | I29: =IFERROR(F29/E29,0) -> 0.6 | J29: 39 | K29: 18 | L29: =J29-K29 -> 21 | M29: =IFERROR(J29/E29,0) -> 1.95 | N29: =IFERROR(K29/E29,0) -> 0.9 | O29: 8 | P29: 3 | Q29: 1 | R29: =IFERROR((3*F29+G29)/(3*E29),0) -> 0.68333333
A30: 26 | B30: Iran | C30: AFC | D30: G | E30: 10 | F30: 9 | G30: 1 | H30: 0 | I30: =IFERROR(F30/E30,0) -> 0.9 | J30: 18 | K30: 7 | L30: =J30-K30 -> 11 | M30: =IFERROR(J30/E30,0) -> 1.8 | N30: =IFERROR(K30/E30,0) -> 0.7 | O30: 4 | P30: 5 | Q30: 0.72 | R30: =IFERROR((3*F30+G30)/(3*E30),0) -> 0.93333333
A31: 27 | B31: Egypt | C31: CAF | D31: G | E31: 10 | F31: 8 | G31: 2 | H31: 0 | I31: =IFERROR(F31/E31,0) -> 0.8 | J31: 20 | K31: 2 | L31: =J31-K31 -> 18 | M31: =IFERROR(J31/E31,0) -> 2 | N31: =IFERROR(K31/E31,0) -> 0.2 | O31: 4 | P31: 5 | Q31: 0.9 | R31: =IFERROR((3*F31+G31)/(3*E31),0) -> 0.86666667
A32: 28 | B32: New Zealand | C32: OFC | D32: G | E32: 5 | F32: 1 | G32: 2 | H32: 2 | I32: =IFERROR(F32/E32,0) -> 0.2 | J32: 6 | K32: 8 | L32: =J32-K32 -> -2 | M32: =IFERROR(J32/E32,0) -> 1.2 | N32: =IFERROR(K32/E32,0) -> 1.6 | O32: 2 | P32: Level-adjusted: raw OFC qualifying was 5-0-0, 29 GF/1 GA vs Pacific minnows — non-predictive at WC level | Q32: 1 | R32: =IFERROR((3*F32+G32)/(3*E32),0) -> 0.33333333
A33: 29 | B33: Spain | C33: UEFA | D33: H | E33: 20 | F33: 15 | G33: 4 | H33: 1 | I33: =IFERROR(F33/E33,0) -> 0.75 | J33: 48 | K33: 12 | L33: =J33-K33 -> 36 | M33: =IFERROR(J33/E33,0) -> 2.4 | N33: =IFERROR(K33/E33,0) -> 0.6 | O33: 12 | P33: 0 | Q33: 1 | R33: =IFERROR((3*F33+G33)/(3*E33),0) -> 0.81666667
A34: 30 | B34: Uruguay | C34: CONMEBOL | D34: H | E34: 24 | F34: 10 | G34: 9 | H34: 5 | I34: =IFERROR(F34/E34,0) -> 0.41666667 | J34: 33 | K34: 16 | L34: =J34-K34 -> 17 | M34: =IFERROR(J34/E34,0) -> 1.375 | N34: =IFERROR(K34/E34,0) -> 0.66666667 | O34: 6 | P34: CONMEBOL quals + Copa America 2024 THIRD PLACE (beat Brazil on pens QF, lost Colombia SF). Strong, defensive. | Q34: 1.12 | R34: =IFERROR((3*F34+G34)/(3*E34),0) -> 0.54166667
A35: 31 | B35: Saudi Arabia | C35: AFC | D35: H | E35: 12 | F35: 4 | G35: 5 | H35: 3 | I35: =IFERROR(F35/E35,0) -> 0.33333333 | J35: 11 | K35: 11 | L35: =J35-K35 -> 0 | M35: =IFERROR(J35/E35,0) -> 0.91666667 | N35: =IFERROR(K35/E35,0) -> 0.91666667 | O35: 3 | P35: 6 | Q35: 0.72 | R35: =IFERROR((3*F35+G35)/(3*E35),0) -> 0.47222222
A36: 32 | B36: Cape Verde | C36: CAF | D36: H | E36: 10 | F36: 7 | G36: 2 | H36: 1 | I36: =IFERROR(F36/E36,0) -> 0.7 | J36: 16 | K36: 8 | L36: =J36-K36 -> 8 | M36: =IFERROR(J36/E36,0) -> 1.6 | N36: =IFERROR(K36/E36,0) -> 0.8 | O36: 3 | P36: 7 | Q36: 0.72 | R36: =IFERROR((3*F36+G36)/(3*E36),0) -> 0.76666667
A37: 33 | B37: France | C37: UEFA | D37: I | E37: 20 | F37: 16 | G37: 3 | H37: 1 | I37: =IFERROR(F37/E37,0) -> 0.8 | J37: 45 | K37: 11 | L37: =J37-K37 -> 34 | M37: =IFERROR(J37/E37,0) -> 2.25 | N37: =IFERROR(K37/E37,0) -> 0.55 | O37: 12 | P37: 1 | Q37: 1 | R37: =IFERROR((3*F37+G37)/(3*E37),0) -> 0.85
A38: 34 | B38: Senegal | C38: CAF | D38: I | E38: 10 | F38: 7 | G38: 3 | H38: 0 | I38: =IFERROR(F38/E38,0) -> 0.7 | J38: 22 | K38: 3 | L38: =J38-K38 -> 19 | M38: =IFERROR(J38/E38,0) -> 2.2 | N38: =IFERROR(K38/E38,0) -> 0.3 | O38: 5 | P38: 4 | Q38: 0.92 | R38: =IFERROR((3*F38+G38)/(3*E38),0) -> 0.8
A39: 35 | B39: Norway | C39: UEFA | D39: I | E39: 13 | F39: 9 | G39: 2 | H39: 2 | I39: =IFERROR(F39/E39,0) -> 0.69230769 | J39: 42 | K39: 14 | L39: =J39-K39 -> 28 | M39: =IFERROR(J39/E39,0) -> 3.2307692 | N39: =IFERROR(K39/E39,0) -> 1.0769231 | O39: 5 | P39: Qual 8-0-0 (incl 2x Italy) BUT padded by 11-1 Moldova. Strong-opp overlay: L Netherlands, D Switzerland, D Morocco, L Austria 1-5, W Austria. Perfect record didn't hold up. | Q39: 0.98 | R39: =IFERROR((3*F39+G39)/(3*E39),0) -> 0.74358974
A40: 36 | B40: Iraq | C40: AFC | D40: I | E40: 14 | F40: 6 | G40: 5 | H40: 3 | I40: =IFERROR(F40/E40,0) -> 0.42857143 | J40: 15 | K40: 13 | L40: =J40-K40 -> 2 | M40: =IFERROR(J40/E40,0) -> 1.0714286 | N40: =IFERROR(K40/E40,0) -> 0.92857143 | O40: 3 | P40: 7 | Q40: 0.72 | R40: =IFERROR((3*F40+G40)/(3*E40),0) -> 0.54761905
...

Sheet Squad_History
A1: SQUAD DYNAMICS & TOURNAMENT DNA
A2: 🟦 Edit BLUE cells. Update after FIFA squad deadline (May 30).
A3: 🟦 BLUE cells = your inputs (edit these) ◾ GREY cells = locked formulas (don't edit)
A4: # | B4: Team | C4: Group | D4: Star Player | E4: Pos | F4: Qual Goals | G4: Qual Assists | H4: Key Player 2 | I4: Key Player 3 | J4: Avg Age | K4: WC Apps (ref) | L4: Best Finish (ref)
A5: 1 | B5: Mexico | C5: A | D5: Edson Álvarez | E5: DM | F5: 2 | G5: 3 | H5: Santiago Giménez | I5: Hirving Lozano | J5: 27.2 | K5: 17 | L5: QF (1970, 1986)
A6: 2 | B6: South Korea | C6: A | D6: Son Heung-min | E6: LW | F6: 7 | G6: 3 | H6: Kim Min-jae | I6: Lee Kang-in | J6: 27.1 | K6: 11 | L6: 4th (2002)
A7: 3 | B7: South Africa | C7: A | D7: Percy Tau | E7: AM | F7: 4 | G7: 3 | H7: Themba Zwane | I7: Ronwen Williams | J7: 27.8 | K7: 4 | L7: Group (Host 2010)
A8: 4 | B8: Czechia | C8: A | D8: Patrik Schick | E8: ST | F8: 5 | G8: 2 | H8: Tomáš Souček | I8: Adam Hložek | J8: 27.5 | K8: 10 | L8: Runner-up (1934, 1962)
A9: 5 | B9: Canada | C9: B | D9: Alphonso Davies | E9: LB | F9: 2 | G9: 4 | H9: Jonathan David | I9: Stephen Eustáquio | J9: 27 | K9: 3 | L9: Group (1986, 2022)
A10: 6 | B10: Switzerland | C10: B | D10: Granit Xhaka | E10: DM | F10: 3 | G10: 4 | H10: Manuel Akanji | I10: Breel Embolo | J10: 28.4 | K10: 12 | L10: QF (1934, 1938, 1954)
A11: 7 | B11: Qatar | C11: B | D11: Akram Afif | E11: AM | F11: 6 | G11: 4 | H11: Almoez Ali | I11: Hassan Al-Haydos | J11: 28.3 | K11: 2 | L11: Group (2022)
A12: 8 | B12: Bosnia and Herzegovina | C12: B | D12: Edin Džeko | E12: ST | F12: 6 | G12: 3 | H12: Miralem Pjanić | I12: Sead Kolašinac | J12: 29.1 | K12: 2 | L12: Group (2014)
A13: 9 | B13: Brazil | C13: C | D13: Vinícius Júnior | E13: LW | F13: 7 | G13: 5 | H13: Rodrygo | I13: Casemiro | J13: 27.5 | K13: 23 | L13: Champion (1958-2002 x5)
A14: 10 | B14: Morocco | C14: C | D14: Achraf Hakimi | E14: RB | F14: 4 | G14: 6 | H14: Hakim Ziyech | I14: Sofyan Amrabat | J14: 27.3 | K14: 7 | L14: 4th (2022)
A15: 11 | B15: Scotland | C15: C | D15: Scott McTominay | E15: CM | F15: 5 | G15: 3 | H15: Andy Robertson | I15: John McGinn | J15: 28.6 | K15: 9 | L15: Group
A16: 12 | B16: Haiti | C16: C | D16: Duckens Nazon | E16: ST | F16: 4 | G16: 1 | H16: Frantzdy Pierrot | I16: Carlens Arcus | J16: 27.9 | K16: 2 | L16: Group (1974)
... A52: 48 | B52: Ghana | C52: L | D52: Mohammed Kudus | E52: AM | F52: 4 | G52: 3 | H52: Thomas Partey | I52: Jordan Ayew | J52: 27 | K52: 5 | L52: QF (2010)
A54: ⚠ SQUAD REVIEW ALERT — June 12, 2026
A55: FIFA 26-man squad deadline was May 30. Refresh the BLUE input cells with final selections.

Sheet Tactics
A1: TACTICAL MAPPING — Styles & Formations
A2: 🟦 Edit BLUE cells. Pressing (1-10), Possession % and Pass Acc % feed the prediction engine.
A3: 🟦 BLUE cells = your inputs (edit these) ◾ GREY cells = locked formulas (don't edit)
A4: # | B4: Team | C4: Group | D4: Formation | E4: Playing Style | F4: Build-up | G4: Defensive Block | H4: Pressing (1-10) | I4: Possession % | J4: Pass Acc. % | K4: Weakness vs | L4: Strength vs
A5: 1 | B5: Mexico | C5: A | D5: 4-3-3 | E5: Possession + Counter | F5: Mixed | G5: Mid block | H5: 7 | I5: 55 | J5: 83 | K5: Aerial duels | L5: Quick combinations
A6: 2 | B6: South Korea | C6: A | D6: 4-2-3-1 | E6: Counter + Press | F6: Mixed | G6: Mid block | H6: 7 | I6: 52 | J6: 82 | K6: Aerial dominance | L6: Pace on counter
A7: 3 | B7: South Africa | C7: A | D7: 4-3-3 | E7: Possession | F7: Patient build-up | G7: Mid block | H7: 6 | I7: 53 | J7: 79 | K7: Physical pressing | L7: Quick combinations
A8: 4 | B8: Czechia | C8: A | D8: 4-2-3-1 | E8: Counter + Press | F8: Mixed | G8: Mid block | H8: 7 | I8: 51 | J8: 81 | K8: Aerial | L8: Direct transitions
A9: 5 | B9: Canada | C9: B | D9: 4-3-3 | E9: High Press + Counter | F9: Mixed | G9: Mid-high block | H9: 8 | I9: 52 | J9: 81 | K9: Possession press | L9: Athletic transitions
A10: 6 | B10: Switzerland | C10: B | D10: 4-2-3-1 | E10: Counter | F10: Direct build-up | G10: Mid-low block | H10: 6 | I10: 48 | J10: 81 | K10: High press | L10: Defensive shape
A11: 7 | B11: Qatar | C11: B | D11: 3-5-2 | E11: Possession | F11: Short build-up | G11: Mid block | H11: 6 | I11: 53 | J11: 81 | K11: Physical duels | L11: Patient build-up
A12: 8 | B12: Bosnia and Herzegovina | C12: B | D12: 4-2-3-1 | E12: Direct + Counter | F12: Direct | G12: Mid-low block | H12: 6 | I12: 47 | J12: 78 | K12: Possession press | L12: Aerial duels
A13: 9 | B13: Brazil | C13: C | D13: 4-2-3-1 | E13: Possession + Counter | F13: Wide build-up | G13: Mid block | H13: 7 | I13: 58 | J13: 85 | K13: Set-piece defense | L13: Physical teams
A14: 10 | B14: Morocco | C14: C | D14: 4-3-3 / 5-4-1 | E14: Low Block Counter | F14: Direct | G14: Low block | H14: 6 | I14: 42 | J14: 78 | K14: Patient breakdown | L14: Set-piece defense
A15: 11 | B15: Scotland | C15: C | D15: 3-4-2-1 / 3-5-2 | E15: Direct + Press | F15: Mixed | G15: Mid block | H15: 7 | I15: 50 | J15: 80 | K15: Possession | L15: Set-piece threat
A16: 12 | B16: Haiti | C16: C | D16: 4-3-3 | E16: Counter | F16: Direct | G16: Low block | H16: 6 | I16: 42 | J16: 73 | K16: Patient breakdown | L16: Athletic counters
... A52: 48 | B52: Ghana | C52: L | D52: 4-2-3-1 | E52: Counter | F52: Direct | G52: Mid-low block | H52: 6 | I52: 47 | J52: 76 | K52: Possession | L52: Set pieces

Sheet Goal_Sources
A1: GOAL SOURCE ANALYSIS — Offensive & Defensive
A2: 🟦 Edit BLUE % cells. The 'Total' column should add to ~100%. Heat-mapped per source.
A3: 🟦 BLUE cells = your inputs (edit these) ◾ GREY cells = locked formulas (don't edit)
A4: Team Reference | D4: OFFENSIVE — Where their goals come from (%) | J4: Σ | K4: DEFENSIVE — Where their conceded goals come from (%) | Q4: Σ
A5: # | B5: Team | C5: Group | D5: Open Play | E5: Counter | F5: Corners | G5: Free Kicks | H5: Penalties | I5: Other SP | J5: Total | K5: Open Play | L5: Counter | M5: Corners | N5: Free Kicks | O5: Penalties | P5: Other | Q5: Total
A6: 1 | B6: Mexico | C6: A | D6: 60 | E6: 12 | F6: 12.5 | G6: 7 | H6: 8 | I6: 0.5 | J6: =SUM(D6:I6) -> 100 | K6: 55 | L6: 13 | M6: 14 | N6: 8 | O6: 7 | P6: 3 | Q6: =SUM(K6:P6) -> 100
A7: 2 | B7: South Korea | C7: A | D7: 57 | E7: 10.8 | F7: 13.4 | G7: 7 | H7: 8 | I7: 3.8 | J7: =SUM(D7:I7) -> 100 | K7: 56.8 | L7: 12.4 | M7: 13.4 | N7: 8 | O7: 7 | P7: 2.4 | Q7: =SUM(K7:P7) -> 100
A8: 3 | B8: South Africa | C8: A | D8: 53.5 | E8: 9.4 | F8: 14.5 | G8: 7 | H8: 8 | I8: 7.6 | J8: =SUM(D8:I8) -> 100 | K8: 58.9 | L8: 11.7 | M8: 12.7 | N8: 8 | O8: 7 | P8: 1.7 | Q8: =SUM(K8:P8) -> 100
A9: 4 | B9: Czechia | C9: A | D9: 55.5 | E9: 10.2 | F9: 13.9 | G9: 7 | H9: 8 | I9: 5.4 | J9: =SUM(D9:I9) -> 100 | K9: 57.7 | L9: 12.1 | M9: 13.1 | N9: 8 | O9: 7 | P9: 2.1 | Q9: =SUM(K9:P9) -> 100
A10: 5 | B10: Canada | C10: B | D10: 56.5 | E10: 10.6 | F10: 13.6 | G10: 7 | H10: 8 | I10: 4.3 | J10: =SUM(D10:I10) -> 100 | K10: 57.1 | L10: 12.3 | M10: 13.3 | N10: 8 | O10: 7 | P10: 2.3 | Q10: =SUM(K10:P10) -> 100
A11: 6 | B11: Switzerland | C11: B | D11: 59.5 | E11: 11.8 | F11: 12.7 | G11: 7 | H11: 8 | I11: 1 | J11: =SUM(D11:I11) -> 100 | K11: 55.3 | L11: 12.9 | M11: 13.9 | N11: 8 | O11: 7 | P11: 2.9 | Q11: =SUM(K11:P11) -> 100
A12: 7 | B12: Qatar | C12: B | D12: 53 | E12: 9.2 | F12: 14.6 | G12: 7 | H12: 8 | I12: 8.2 | J12: =SUM(D12:I12) -> 100 | K12: 59.2 | L12: 11.6 | M12: 12.6 | N12: 8 | O12: 7 | P12: 1.6 | Q12: =SUM(K12:P12) -> 100
A13: 8 | B13: Bosnia and Herzegovina | C13: B | D13: 54 | E13: 9.6 | F13: 14.3 | G13: 7 | H13: 8 | I13: 7.1 | J13: =SUM(D13:I13) -> 100 | K13: 58.6 | L13: 11.8 | M13: 12.8 | N13: 8 | O13: 7 | P13: 1.8 | Q13: =SUM(K13:P13) -> 100
A14: 9 | B14: Brazil | C14: C | D14: 65 | E14: 14 | F14: 11 | G14: 7 | H14: 8 | I14: 0 | J14: =SUM(D14:I14) -> 105 | K14: 52 | L14: 14 | M14: 15 | N14: 8 | O14: 7 | P14: 4 | Q14: =SUM(K14:P14) -> 100
A15: 10 | B15: Morocco | C15: C | D15: 60.5 | E15: 12.2 | F15: 12.4 | G15: 7 | H15: 8 | I15: 0 | J15: =SUM(D15:I15) -> 100.1 | K15: 54.7 | L15: 13.1 | M15: 14.1 | N15: 8 | O15: 7 | P15: 3.1 | Q15: =SUM(K15:P15) -> 100
A16: 11 | B16: Scotland | C16: C | D16: 55 | E16: 10 | F16: 14 | G16: 7 | H16: 8 | I16: 6 | J16: =SUM(D16:I16) -> 100 | K16: 58 | L16: 12 | M16: 13 | N16: 8 | O16: 7 | P16: 2 | Q16: =SUM(K16:P16) -> 100
A17: 12 | B17: Haiti | C17: C | D17: 49 | E17: 7.6 | F17: 15.8 | G17: 7 | H17: 8 | I17: 12.6 | J17: =SUM(D17:I17) -> 100 | K17: 61.6 | L17: 10.8 | M17: 11.8 | N17: 8 | O17: 7 | P17: 0.8 | Q17: =SUM(K17:P17) -> 100
... A53: 48 | B53: Ghana | C53: L | D53: 54 | E53: 9.6 | F53: 14.3 | G53: 7 | H53: 8 | I53: 7.1 | J53: =SUM(D53:I53) -> 100 | K53: 58.6 | L53: 11.8 | M53: 12.8 | N53: 8 | O53: 7 | P53: 1.8 | Q53: =SUM(K53:P53) -> 100

Sheet Goal_Timing
A1: GOAL TIMING & MATCH FLOW — 15-Min Intervals
A2: 🟦 Edit BLUE % cells. Peak Scoring / Vulnerability windows compute automatically.
A3: 🟦 BLUE cells = your inputs (edit these) ◾ GREY cells = locked formulas (don't edit)
A4: Team Reference | D4: SCORED (%) — When they score | J4: Σ | K4: CONCEDED (%) — When they concede | Q4: Σ | R4: Peak Windows (auto)
A5: # | B5: Team | C5: Group | D5: 0-15 | E5: 16-30 | F5: 31-45 | G5: 46-60 | H5: 61-75 | I5: 76-90 | J5: Σ | K5: 0-15 | L5: 16-30 | M5: 31-45 | N5: 46-60 | O5: 61-75 | P5: 76-90 | Q5: Σ | R5: Peak Scoring | S5: Peak Vulnerable
A6: 1 | B6: Mexico | C6: A | D6: 11 | E6: 14 | F6: 17 | G6: 16 | H6: 19 | I6: 23 | J6: =SUM(D6:I6) -> 100 | K6: 10 | L6: 13 | M6: 15 | N6: 17 | O6: 19 | P6: 26 | Q6: =SUM(K6:P6) -> 100 | R6: =INDEX($D$5:$I$5,MATCH(MAX(D6:I6),D6:I6,0)) -> 76-90 | S6: =INDEX($K$5:$P$5,MATCH(MAX(K6:P6),K6:P6,0)) -> 76-90
A7: 2 | B7: South Korea | C7: A | D7: 12 | E7: 15 | F7: 18 | G7: 16 | H7: 18 | I7: 21 | J7: =SUM(D7:I7) -> 100 | K7: 14 | L7: 16 | M7: 16 | N7: 17 | O7: 18 | P7: 19 | Q7: =SUM(K7:P7) -> 100 | R7: =INDEX($D$5:$I$5,MATCH(MAX(D7:I7),D7:I7,0)) -> 76-90 | S7: =INDEX($K$5:$P$5,MATCH(MAX(K7:P7),K7:P7,0)) -> 76-90
A8: 3 | B8: South Africa | C8: A | D8: 12 | E8: 15 | F8: 18 | G8: 16 | H8: 18 | I8: 21 | J8: =SUM(D8:I8) -> 100 | K8: 18 | L8: 17 | M8: 17 | N8: 16 | O8: 16 | P8: 16 | Q8: =SUM(K8:P8) -> 100 | R8: =INDEX($D$5:$I$5,MATCH(MAX(D8:I8),D8:I8,0)) -> 76-90 | S8: =INDEX($K$5:$P$5,MATCH(MAX(K8:P8),K8:P8,0)) -> 0-15
A9: 4 | B9: Czechia | C9: A | D9: 12 | E9: 15 | F9: 18 | G9: 16 | H9: 18 | I9: 21 | J9: =SUM(D9:I9) -> 100 | K9: 14 | L9: 16 | M9: 16 | N9: 17 | O9: 18 | P9: 19 | Q9: =SUM(K9:P9) -> 100 | R9: =INDEX($D$5:$I$5,MATCH(MAX(D9:I9),D9:I9,0)) -> 76-90 | S9: =INDEX($K$5:$P$5,MATCH(MAX(K9:P9),K9:P9,0)) -> 76-90
A10: 5 | B10: Canada | C10: B | D10: 12 | E10: 15 | F10: 18 | G10: 16 | H10: 18 | I10: 21 | J10: =SUM(D10:I10) -> 100 | K10: 14 | L10: 16 | M10: 16 | N10: 17 | O10: 18 | P10: 19 | Q10: =SUM(K10:P10) -> 100 | R10: =INDEX($D$5:$I$5,MATCH(MAX(D10:I10),D10:I10,0)) -> 76-90 | S10: =INDEX($K$5:$P$5,MATCH(MAX(K10:P10),K10:P10,0)) -> 76-90
A11: 6 | B11: Switzerland | C11: B | D11: 12 | E11: 15 | F11: 18 | G11: 16 | H11: 18 | I11: 21 | J11: =SUM(D11:I11) -> 100 | K11: 14 | L11: 16 | M11: 16 | N11: 17 | O11: 18 | P11: 19 | Q11: =SUM(K11:P11) -> 100 | R11: =INDEX($D$5:$I$5,MATCH(MAX(D11:I11),D11:I11,0)) -> 76-90 | S11: =INDEX($K$5:$P$5,MATCH(MAX(K11:P11),K11:P11,0)) -> 76-90
A12: 7 | B12: Qatar | C12: B | D12: 12 | E12: 15 | F12: 18 | G12: 16 | H12: 18 | I12: 21 | J12: =SUM(D12:I12) -> 100 | K12: 18 | L12: 17 | M12: 17 | N12: 16 | O12: 16 | P12: 16 | Q12: =SUM(K12:P12) -> 100 | R12: =INDEX($D$5:$I$5,MATCH(MAX(D12:I12),D12:I12,0)) -> 76-90 | S12: =INDEX($K$5:$P$5,MATCH(MAX(K12:P12),K12:P12,0)) -> 0-15
A13: 8 | B13: Bosnia and Herzegovina | C13: B | D13: 12 | E13: 15 | F13: 18 | G13: 16 | H13: 18 | I13: 21 | J13: =SUM(D13:I13) -> 100 | K13: 18 | L13: 17 | M13: 17 | N13: 16 | O13: 16 | P13: 16 | Q13: =SUM(K13:P13) -> 100 | R13: =INDEX($D$5:$I$5,MATCH(MAX(D13:I13),D13:I13,0)) -> 76-90 | S13: =INDEX($K$5:$P$5,MATCH(MAX(K13:P13),K13:P13,0)) -> 0-15
A14: 9 | B14: Brazil | C14: C | D14: 11 | E14: 14 | F14: 17 | G14: 16 | H14: 19 | I14: 23 | J14: =SUM(D14:I14) -> 100 | K14: 10 | L14: 13 | M14: 15 | N14: 17 | O14: 19 | P14: 26 | Q14: =SUM(K14:P14) -> 100 | R14: =INDEX($D$5:$I$5,MATCH(MAX(D14:I14),D14:I14,0)) -> 76-90 | S14: =INDEX($K$5:$P$5,MATCH(MAX(K14:P14),K14:P14,0)) -> 76-90
A15: 10 | B15: Morocco | C15: C | D15: 11 | E15: 14 | F15: 17 | G15: 16 | H15: 19 | I15: 23 | J15: =SUM(D15:I15) -> 100 | K15: 10 | L15: 13 | M15: 15 | N15: 17 | O15: 19 | P15: 26 | Q15: =SUM(K15:P15) -> 100 | R15: =INDEX($D$5:$I$5,MATCH(MAX(D15:I15),D15:I15,0)) -> 76-90 | S15: =INDEX($K$5:$P$5,MATCH(MAX(K15:P15),K15:P15,0)) -> 76-90
A16: 11 | B16: Scotland | C16: C | D16: 12 | E16: 15 | F16: 18 | G16: 16 | H16: 18 | I16: 21 | J16: =SUM(D16:I16) -> 100 | K16: 14 | L16: 16 | M16: 16 | N16: 17 | O16: 18 | P16: 19 | Q16: =SUM(K16:P16) -> 100 | R16: =INDEX($D$5:$I$5,MATCH(MAX(D16:I16),D16:I16,0)) -> 76-90 | S16: =INDEX($K$5:$P$5,MATCH(MAX(K16:P16),K16:P16,0)) -> 76-90
A17: 12 | B17: Haiti | C17: C | D17: 14 | E17: 16 | F17: 18 | G17: 17 | H17: 17 | I17: 18 | J17: =SUM(D17:I17) -> 100 | K17: 18 | L17: 17 | M17: 17 | N17: 16 | O17: 16 | P17: 16 | Q17: =SUM(K17:P17) -> 100 | R17: =INDEX($D$5:$I$5,MATCH(MAX(D17:I17),D17:I17,0)) -> 31-45 | S17: =INDEX($K$5:$P$5,MATCH(MAX(K17:P17),K17:P17,0)) -> 0-15
... A53: 48 | B53: Ghana | C53: L | D53: 12 | E53: 15 | F53: 18 | G53: 16 | H53: 18 | I53: 21 | J53: =SUM(D53:I53) -> 100 | K53: 18 | L53: 17 | M53: 17 | N53: 16 | O53: 16 | P53: 16 | Q53: =SUM(K53:P53) -> 100 | R53: =INDEX($D$5:$I$5,MATCH(MAX(D53:I53),D53:I53,0)) -> 76-90 | S53: =INDEX($K$5:$P$5,MATCH(MAX(K53:P53),K53:P53,0)) -> 0-15

Sheet Group_Standings
A1: PROJECTED GROUP STANDINGS — First Round (Group Stage)
A2: Expected points from all 72 predicted matches (3 played results locked). Top 2 per group + 8 best 3rd-place teams advance.
A4: GROUP A | G4: GROUP B
A5: # | B5: Team | C5: xPts | D5: xGD | E5: Status | G5: # | H5: Team | I5: xPts | J5: xGD | K5: Status
A6: 1 | B6: South Korea | C6: 6.5 | D6: 2 | E6: Advance (1st/2nd) | G6: 1 | H6: Switzerland | I6: 7.65 | J6: 3 | K6: Advance (1st/2nd)
A7: 2 | B7: Mexico | C7: 5.03 | D7: 2 | E7: Advance (1st/2nd) | G7: 2 | H7: Bosnia and Herzegovina | I7: 3.92 | J7: 0 | K7: Advance (1st/2nd)
A8: 3 | B8: Czechia | C8: 3.55 | D8: 0 | E8: Advance (best 3rd) | G8: 3 | H8: Canada | I8: 3.47 | J8: 0 | K8: Eliminated
A9: 4 | B9: South Africa | C9: 1.31 | D9: -4 | E9: Eliminated | G9: 4 | H9: Qatar | I9: 0.92 | J9: -3 | K9: Eliminated
A11: GROUP C | G11: GROUP D
A12: # | B12: Team | C12: xPts | D12: xGD | E12: Status | G12: # | H12: Team | I12: xPts | J12: xGD | K12: Status
A13: 1 | B13: Brazil | C13: 5.81 | D13: 1 | E13: Advance (1st/2nd) | G13: 1 | H13: Türkiye | I13: 6.93 | J13: 3 | K13: Advance (1st/2nd)
A14: 2 | B14: Morocco | C14: 4.81 | D14: 1 | E14: Advance (1st/2nd) | G14: 2 | H14: Australia | I14: 3.41 | J14: -1 | K14: Advance (1st/2nd)
A15: 3 | B15: Scotland | C15: 4.52 | D15: 1 | E15: Advance (best 3rd) | G15: 3 | H15: United States | I15: 2.75 | J15: -1 | K15: Eliminated
A16: 4 | B16: Haiti | C16: 0.88 | D16: -3 | E16: Eliminated | G16: 4 | H16: Paraguay | I16: 2.65 | J16: -1 | K16: Eliminated
A18: GROUP E | G18: GROUP F
A19: # | B19: Team | C19: xPts | D19: xGD | E19: Status | G19: # | H19: Team | I19: xPts | J19: xGD | K19: Status
A20: 1 | B20: Ivory Coast | C20: 5.78 | D20: 3 | E20: Advance (1st/2nd) | G20: 1 | H20: Netherlands | I20: 5.62 | J20: 1 | K20: Advance (1st/2nd)
A21: 2 | B21: Germany | C21: 5.05 | D21: 1 | E21: Advance (1st/2nd) | G21: 2 | H21: Japan | I21: 4.89 | J21: 2 | K21: Advance (1st/2nd)
A22: 3 | B22: Ecuador | C22: 3.49 | D22: -1 | E22: Advance (best 3rd) | G22: 3 | H22: Tunisia | I22: 4.83 | J22: 1 | K22: Advance (best 3rd)
A23: 4 | B23: Curaçao | C23: 1.56 | D23: -3 | E23: Eliminated | G23: 4 | H23: Sweden | I23: 0.58 | J23: -4 | K23: Eliminated
A25: GROUP G | G25: GROUP H
A26: # | B26: Team | C26: xPts | D26: xGD | E26: Status | G26: # | H26: Team | I26: xPts | J26: xGD | K26: Status
A27: 1 | B27: Egypt | C27: 6.94 | D27: 3 | E27: Advance (1st/2nd) | G27: 1 | H27: Spain | I27: 7.75 | J27: 3 | K27: Advance (1st/2nd)
A28: 2 | B28: Belgium | C28: 4.72 | D28: 0 | E28: Advance (1st/2nd) | G28: 2 | H28: Uruguay | I28: 4.52 | J28: 1 | K28: Advance (1st/2nd)
A29: 3 | B29: Iran | C29: 4.08 | D29: 0 | E29: Advance (best 3rd) | G29: 3 | H29: Cape Verde | I29: 3.32 | J29: -1 | K29: Eliminated
A30: 4 | B30: New Zealand | C30: 0.63 | D30: -3 | E30: Eliminated | G30: 4 | H30: Saudi Arabia | I30: 0.97 | J30: -3 | K30: Eliminated
A32: GROUP I | G32: GROUP J
A33: # | B33: Team | C33: xPts | D33: xGD | E33: Status | G33: # | H33: Team | I33: xPts | J33: xGD | K33: Status
A34: 1 | B34: France | C34: 6 | D34: 2 | E34: Advance (1st/2nd) | G34: 1 | H34: Austria | I34: 6.66 | J34: 3 | K34: Advance (1st/2nd)
A35: 2 | B35: Senegal | C35: 5.13 | D35: 1 | E35: Advance (1st/2nd) | G35: 2 | H35: Argentina | I35: 5.33 | J35: 1 | K35: Advance (1st/2nd)
A36: 3 | B36: Norway | C36: 4.38 | D36: 1 | E36: Advance (best 3rd) | G36: 3 | H36: Algeria | I36: 3.72 | J36: -1 | K36: Advance (best 3rd)
A37: 4 | B37: Iraq | C37: 0.61 | D37: -4 | E37: Eliminated | G37: 4 | H37: Jordan | I37: 0.69 | J37: -3 | K37: Eliminated
A39: GROUP K | G39: GROUP L
A40: # | B40: Team | C40: xPts | D40: xGD | E40: Status | G40: # | H40: Team | I40: xPts | J40: xGD | K40: Status
A41: 1 | B41: Portugal | C41: 6.82 | D41: 3 | E41: Advance (1st/2nd) | G41: 1 | H41: England | I41: 6.8 | J41: 3 | K41: Advance (1st/2nd)
A42: 2 | B42: Colombia | C42: 4.68 | D42: 1 | E42: Advance (1st/2nd) | G42: 2 | H42: Croatia | I42: 3.98 | J42: 0 | K42: Advance (1st/2nd)
A43: 3 | B43: DR Congo | C43: 2.6 | D43: -2 | E43: Eliminated | G43: 3 | H43: Ghana | I43: 3.65 | J43: 0 | K43: Advance (best 3rd)
A44: 4 | B44: Uzbekistan | C44: 1.95 | D44: -2 | E44: Eliminated | G44: 4 | H44: Panama | I44: 1.56 | J44: -3 | K44: Eliminated
A47: 8 BEST THIRD-PLACED TEAMS — also advance
A48: Rank | B48: Group | C48: Team | D48: xPts | E48: xGD
...

Sheet Knockout_Sim
A1: KNOCKOUT SIMULATION — Round of 32 to the Final
A2: Same engine, draws split on penalties. Deterministic path below; Monte Carlo title odds (20,000 sims) at right.
A4: 🏆 PROJECTED CHAMPION: Spain Final: Spain vs Austria (3-2) 🥉 3rd: France
A6: ROUND OF 32 | H6: MONTE CARLO TITLE ODDS (20,000 simulations)
A7: Match | B7: Team A | C7: Team B | D7: Score | E7: Winner | H7: Team | I7: Champion | J7: Finalist | K7: Semi
A8: M73 | B8: Mexico | C8: Bosnia and Herzegovina | D8: 1-2 | E8: Bosnia and Herzegovina | H8: Austria | I8: 0.24365 | J8: 0.4112 | K8: 0.55495
A9: M74 | B9: Ivory Coast | C9: Czechia | D9: 3-2 AET | E9: Ivory Coast | H9: France | I9: 0.20505 | J9: 0.34595 | K9: 0.5902
A10: M75 | B10: Netherlands | C10: Morocco | D10: 2-1 | E10: Netherlands | H10: Spain | I10: 0.1991 | J10: 0.31395 | K10: 0.47665
A11: M76 | B11: Brazil | C11: Japan | D11: 1-2 | E11: Brazil | H11: Switzerland | I11: 0.07065 | J11: 0.1578 | K11: 0.26095
A12: M77 | B12: France | C12: Scotland | D12: 2-1 | E12: France | H12: Senegal | I12: 0.0577 | J12: 0.1301 | K12: 0.29795
A13: M78 | B13: Germany | C13: Senegal | D13: 1-2 | E13: Senegal | H13: England | I13: 0.0516 | J13: 0.1366 | K13: 0.35255
A14: M79 | B14: South Korea | C14: Tunisia | D14: 3-2 AET | E14: South Korea | H14: Egypt | I14: 0.0398 | J14: 0.0967 | K14: 0.20415
A15: M80 | B15: England | C15: Ecuador | D15: 2-0 | E15: England | H15: Netherlands | I15: 0.0353 | J15: 0.0947 | K15: 0.2486
A16: M81 | B16: Türkiye | C16: Norway | D16: 2-3 | E16: Norway | H16: Argentina | I16: 0.02615 | J16: 0.06005 | K16: 0.1316
A17: M82 | B17: Egypt | C17: Algeria | D17: 2-1 | E17: Egypt | H17: Portugal | I17: 0.01965 | J17: 0.05805 | K17: 0.1202
A18: M83 | B18: Colombia | C18: Croatia | D18: 2-1 AET | E18: Colombia | H18: Norway | I18: 0.0162 | J18: 0.0429 | K18: 0.11305
A19: M84 | B19: Spain | C19: Argentina | D19: 2-1 | E19: Spain | H19: Germany | I19: 0.00955 | J19: 0.0305 | K19: 0.10175
... A21: M86 | B21: Austria | C21: Uruguay | D21: 2-0 | E21: Austria | H21: Japan | I21: 0.00515 | J21: 0.0209 | K21: 0.07835
A22: M87 | B22: Portugal | C22: Ghana | D22: 2-1 | E22: Portugal
A23: M88 | B23: Australia | C23: Belgium | D23: 1-2 | E23: Belgium
A25: ROUND OF 16
A26: Match | B26: Team A | C26: Team B | D26: Score | E26: Winner
A27: M89 | B27: Ivory Coast | C27: France | D27: 1-2 | E27: France
A28: M90 | B28: Bosnia and Herzegovina | C28: Netherlands | D28: 1-2 | E28: Netherlands
A29: M91 | B29: Brazil | C29: Senegal | D29: 1-2 | E29: Senegal
A30: M92 | B30: South Korea | C30: England | D30: 1-2 | E30: England
A31: M93 | B31: Colombia | C31: Spain | D31: 1-2 | E31: Spain
A32: M94 | B32: Norway | C32: Egypt | D32: 2-3 AET | E32: Egypt
A33: M95 | B33: Austria | C33: Belgium | D33: 2-1 | E33: Austria
A34: M96 | B34: Switzerland | C34: Portugal | D34: 2-1 | E34: Switzerland
A36: QUARTERFINALS
A37: Match | B37: Team A | C37: Team B | D37: Score | E37: Winner
A38: M97 | B38: France | C38: Netherlands | D38: 2-1 | E38: France
A39: M98 | B39: Spain | C39: Egypt | D39: 2-1 | E39: Spain
A40: M99 | B40: Senegal | C40: England | D40: 2-1 | E40: Senegal
A41: M100 | B41: Austria | C41: Switzerland | D41: 2-1 | E41: Austria
A43: SEMIFINALS
A44: Match | B44: Team A | C44: Team B | D44: Score | E44: Winner
A45: SF1 | B45: France | C45: Spain | D45: 2-3 AET | E45: Spain
A46: SF2 | B46: Senegal | C46: Austria | D46: 1-2 | E46: Austria
...

Sheet Predictions
A1: PREDICTION ENGINE — Every Group-Stage Match
A2: 🟢 Green = cross-sheet pulls. ◾ Grey = computed. 🟦 Blue 'Your Pick' = your override.
A3: 🟦 BLUE cells = your inputs (edit these) ◾ GREY cells = locked formulas (don't edit)
A4: POWER = [ (Win%×40) + (Avg GD/game capped ±2 ×8) ] × Strength-of-Schedule + (PassAcc×0.3)+(Pressing×1.5). SoS (Form_L20 col Q, editable): 11 broad-sample teams=1.00; CONMEBOL quals=1.10; UEFA quals=0.90; CAF/AFC/CONCACAF=0.82. | W4: 🏆 PLACAR DO BOLÃO
A5: Match # | B5: Group | C5: Date | D5: Team A | E5: Team B | F5: Power A | G5: Power B | H5: Δ | I5: Win A % | J5: Draw % | K5: Win B % | L5: Pred. Score | M5: Pred. Result | N5: Confidence | O5: Your Pick | P5: Notes | Q5: Gols Real A | R5: Gols Real B | S5: Resultado Real | T5: Categoria | U5: Pontos | W5: Jogos com resultado | Y5: =SUMPRODUCT((Q6:Q77<>"")*(R6:R77<>"")) -> 3
A6: 1 | B6: A | C6: 46184 | D6: Mexico | E6: South Africa | F6: =ROUND((INDEX(Form_L20!$R$5:$R$52,MATCH(D6,Form_L20!$B$5:$B$52,0))*40+MIN(2,MAX(-2.5,INDEX(Form_L20!$M$5:$M$52,MATCH(D6,Form_L20!$B$5:$B$52,0))-INDEX(Form_L20!$N$5:$N$52,MATCH(D6,Form_L20!$B$5:$B$52,0))))*8+MIN(1.3,MAX(-0.7,1.3-INDEX(Form_L20!$N$5:$N$52,MATCH(D6,Form_L20!$B$5:$B$52,0))))*6)*INDEX(Form_L20!$Q$5:$Q$52,MATCH(D6,Form_L20!$B$5:$B$52,0))+INDEX(Tactics!$J$5:$J$52,MATCH(D6,Tactics!$B$5:$B$52,0))*0.3+INDEX(Tactics!$H$5:$H$52,MATCH(D6,Tactics!$B$5:$B$52,0))*1.5,1) -> 61.7 | G6: =ROUND((INDEX(Form_L20!$R$5:$R$52,MATCH(E6,Form_L20!$B$5:$B$52,0))*40+MIN(2,MAX(-2.5,INDEX(Form_L20!$M$5:$M$52,MATCH(E6,Form_L20!$B$5:$B$52,0))-INDEX(Form_L20!$N$5:$N$52,MATCH(E6,Form_L20!$B$5:$B$52,0))))*8+MIN(1.3,MAX(-0.7,1.3-INDEX(Form_L20!$N$5:$N$52,MATCH(E6,Form_L20!$B$5:$B$52,0))))*6)*INDEX(Form_L20!$Q$5:$Q$52,MATCH(E6,Form_L20!$B$5:$B$52,0))+INDEX(Tactics!$J$5:$J$52,MATCH(E6,Tactics!$B$5:$B$52,0))*0.3+INDEX(Tactics!$H$5:$H$52,MATCH(E6,Tactics!$B$5:$B$52,0))*1.5,1) -> 55.2 | H6: =F6-G6 -> 6.5 | I6: =ROUND((1/(1+10^(-H6/15)))*(1-J6),3) -> 0.42 | J6: =ROUND(MAX(0.19,0.56-ABS(H6)/48),3) -> 0.425 | K6: =ROUND(1-I6-J6,3) -> 0.155 | L6: 3 - 1 | M6: Mexico win | N6: =MAX(I6,J6,K6) -> 0.425 | P6: 🔒 locked (played) | Q6: 2 | R6: 0 | S6: =IF(OR(Q6="",R6=""),"",IF(Q6>R6,D6&" win",IF(R6>Q6,E6&" win","Draw"))) -> Mexico win | T6: =IF(U6="","",CHOOSE(MATCH(U6,{0,5,7,8,9,15},0),"Errou","Apenas Vencedor","Vencedor+Gols","Empate","Vencedor+Saldo","CRAVADA")) -> Vencedor+Saldo | U6: =IF(OR(Q6="",R6=""),"",IF(AND(AA6=Q6,AB6=R6),15,IF(AND(AA6=AB6,Q6=R6),8,IF(AND(AA6>AB6,Q6>R6),IF((AA6-AB6)=(Q6-R6),9,IF(AA6=Q6,7,5)),IF(AND(AA6<AB6,Q6<R6),IF((AB6-AA6)=(R6-Q6),9,IF(AB6=R6,7,5)),0))))) -> 9 | W6: PONTOS TOTAIS | Y6: =SUMIF(U6:U77,">=0") -> 24 | AA6: =IFERROR(VALUE(LEFT(L6,FIND(" - ",L6)-1)),"") -> 3 | AB6: =IFERROR(VALUE(MID(L6,FIND(" - ",L6)+3,10)),"") -> 1 | AC6: =INDEX(Form_L20!$M$5:$M$52,MATCH(D6,Form_L20!$B$5:$B$52,0))*0.6+INDEX(Form_L20!$N$5:$N$52,MATCH(E6,Form_L20!$B$5:$B$52,0))*0.4 -> 1.1165217 | AD6: =INDEX(Form_L20!$M$5:$M$52,MATCH(E6,Form_L20!$B$5:$B$52,0))*0.6+INDEX(Form_L20!$N$5:$N$52,MATCH(D6,Form_L20!$B$5:$B$52,0))*0.4 -> 1.1956522
A7: 2 | B7: A | C7: 46184 | D7: South Korea | E7: Czechia | F7: =ROUND((INDEX(Form_L20!$R$5:$R$52,MATCH(D7,Form_L20!$B$5:$B$52,0))*40+MIN(2,MAX(-2.5,INDEX(Form_L20!$M$5:$M$52,MATCH(D7,Form_L20!$B$5:$B$52,0))-INDEX(Form_L20!$N$5:$N$52,MATCH(D7,Form_L20!$B$5:$B$52,0))))*8+MIN(1.3,MAX(-0.7,1.3-INDEX(Form_L20!$N$5:$N$52,MATCH(D7,Form_L20!$B$5:$B$52,0))))*6)*INDEX(Form_L20!$Q$5:$Q$52,MATCH(D7,Form_L20!$B$5:$B$52,0))+INDEX(Tactics!$J$5:$J$52,MATCH(D7,Tactics!$B$5:$B$52,0))*0.3+INDEX(Tactics!$H$5:$H$52,MATCH(D7,Tactics!$B$5:$B$52,0))*1.5,1) -> 65.8 | G7: =ROUND((INDEX(Form_L20!$R$5:$R$52,MATCH(E7,Form_L20!$B$5:$B$52,0))*40+MIN(2,MAX(-2.5,INDEX(Form_L20!$M$5:$M$52,MATCH(E7,Form_L20!$B$5:$B$52,0))-INDEX(Form_L20!$N$5:$N$52,MATCH(E7,Form_L20!$B$5:$B$52,0))))*8+MIN(1.3,MAX(-0.7,1.3-INDEX(Form_L20!$N$5:$N$52,MATCH(E7,Form_L20!$B$5:$B$52,0))))*6)*INDEX(Form_L20!$Q$5:$Q$52,MATCH(E7,Form_L20!$B$5:$B$52,0))+INDEX(Tactics!$J$5:$J$52,MATCH(E7,Tactics!$B$5:$B$52,0))*0.3+INDEX(Tactics!$H$5:$H$52,MATCH(E7,Tactics!$B$5:$B$52,0))*1.5,1) -> 66.1 | H7: =F7-G7 -> -0.3 | I7: =ROUND((1/(1+10^(-H7/15)))*(1-J7),3) -> 0.218 | J7: =ROUND(MAX(0.19,0.56-ABS(H7)/48),3) -> 0.554 | K7: =ROUND(1-I7-J7,3) -> 0.228 | L7: 2 - 1 | M7: South Korea win | N7: =MAX(I7,J7,K7) -> 0.554 | P7: 🔒 locked (played) | Q7: 2 | R7: 1 | S7: =IF(OR(Q7="",R7=""),"",IF(Q7>R7,D7&" win",IF(R7>Q7,E7&" win","Draw"))) -> South Korea win | T7: =IF(U7="","",CHOOSE(MATCH(U7,{0,5,7,8,9,15},0),"Errou","Apenas Vencedor","Vencedor+Gols","Empate","Vencedor+Saldo","CRAVADA")) -> CRAVADA | U7: =IF(OR(Q7="",R7=""),"",IF(AND(AA7=Q7,AB7=R7),15,IF(AND(AA7=AB7,Q7=R7),8,IF(AND(AA7>AB7,Q7>R7),IF((AA7-AB7)=(Q7-R7),9,IF(AA7=Q7,7,5)),IF(AND(AA7<AB7,Q7<R7),IF((AB7-AA7)=(R7-Q7),9,IF(AB7=R7,7,5)),0))))) -> 15 | W7: Média / jogo | Y7: =IFERROR(SUMIF(U6:U77,">=0")/SUMPRODUCT((Q6:Q77<>"")*(R6:R77<>"")),0) -> 8 | AA7: =IFERROR(VALUE(LEFT(L7,FIND(" - ",L7)-1)),"") -> 2 | AB7: =IFERROR(VALUE(MID(L7,FIND(" - ",L7)+3,10)),"") -> 1 | AC7: =INDEX(Form_L20!$M$5:$M$52,MATCH(D7,Form_L20!$B$5:$B$52,0))*0.6+INDEX(Form_L20!$N$5:$N$52,MATCH(E7,Form_L20!$B$5:$B$52,0))*0.4 -> 1.8 | AD7: =INDEX(Form_L20!$M$5:$M$52,MATCH(E7,Form_L20!$B$5:$B$52,0))*0.6+INDEX(Form_L20!$N$5:$N$52,MATCH(D7,Form_L20!$B$5:$B$52,0))*0.4 -> 1.8
A8: 3 | B8: B | C8: 46185 | D8: Canada | E8: Bosnia and Herzegovina | F8: =ROUND((INDEX(Form_L20!$R$5:$R$52,MATCH(D8,Form_L20!$B$5:$B$52,0))*40+MIN(2,MAX(-2.5,INDEX(Form_L20!$M$5:$M$52,MATCH(D8,Form_L20!$B$5:$B$52,0))-INDEX(Form_L20!$N$5:$N$52,MATCH(D8,Form_L20!$B$5:$B$52,0))))*8+MIN(1.3,MAX(-0.7,1.3-INDEX(Form_L20!$N$5:$N$52,MATCH(D8,Form_L20!$B$5:$B$52,0))))*6)*INDEX(Form_L20!$Q$5:$Q$52,MATCH(D8,Form_L20!$B$5:$B$52,0))+INDEX(Tactics!$J$5:$J$52,MATCH(D8,Tactics!$B$5:$B$52,0))*0.3+INDEX(Tactics!$H$5:$H$52,MATCH(D8,Tactics!$B$5:$B$52,0))*1.5,1) -> 55.9 | G8: =ROUND((INDEX(Form_L20!$R$5:$R$52,MATCH(E8,Form_L20!$B$5:$B$52,0))*40+MIN(2,MAX(-2.5,INDEX(Form_L20!$M$5:$M$52,MATCH(E8,Form_L20!$B$5:$B$52,0))-INDEX(Form_L20!$N$5:$N$52,MATCH(E8,Form_L20!$B$5:$B$52,0))))*8+MIN(1.3,MAX(-0.7,1.3-INDEX(Form_L20!$N$5:$N$52,MATCH(E8,Form_L20!$B$5:$B$52,0))))*6)*INDEX(Form_L20!$Q$5:$Q$52,MATCH(E8,Form_L20!$B$5:$B$52,0))+INDEX(Tactics!$J$5:$J$52,MATCH(E8,Tactics!$B$5:$B$52,0))*0.3+INDEX(Tactics!$H$5:$H$52,MATCH(E8,Tactics!$B$5:$B$52,0))*1.5,1) -> 66.7 | H8: =F8-G8 -> -10.8 | I8: =ROUND((1/(1+10^(-H8/15)))*(1-J8),3) -> 0.106 | J8: =ROUND(MAX(0.19,0.56-ABS(H8)/48),3) -> 0.335 | K8: =ROUND(1-I8-J8,3) -> 0.559 | L8: 2 - 1 | M8: Canada win | N8: =MAX(I8,J8,K8) -> 0.559 | P8: 🔒 locked (played) | Q8: 1 | R8: 1 | S8: =IF(OR(Q8="",R8=""),"",IF(Q8>R8,D8&" win",IF(R8>Q8,E8&" win","Draw"))) -> Draw | T8: =IF(U8="","",CHOOSE(MATCH(U8,{0,5,7,8,9,15},0),"Errou","Apenas Vencedor","Vencedor+Gols","Empate","Vencedor+Saldo","CRAVADA")) -> Errou | U8: =IF(OR(Q8="",R8=""),"",IF(AND(AA8=Q8,AB8=R8),15,IF(AND(AA8=AB8,Q8=R8),8,IF(AND(AA8>AB8,Q8>R8),IF((AA8-AB8)=(Q8-R8),9,IF(AA8=Q8,7,5)),IF(AND(AA8<AB8,Q8<R8),IF((AB8-AA8)=(R8-Q8),9,IF(AB8=R8,7,5)),0))))) -> 0 | W8: Cravadas (15) | Y8: =COUNTIF(U6:U77,15) -> 1 | AA8: =IFERROR(VALUE(LEFT(L8,FIND(" - ",L8)-1)),"") -> 2 | AB8: =IFERROR(VALUE(MID(L8,FIND(" - ",L8)+3,10)),"") -> 1 | AC8: =INDEX(Form_L20!$M$5:$M$52,MATCH(D8,Form_L20!$B$5:$B$52,0))*0.6+INDEX(Form_L20!$N$5:$N$52,MATCH(E8,Form_L20!$B$5:$B$52,0))*0.4 -> 1.08 | AD8: =INDEX(Form_L20!$M$5:$M$52,MATCH(E8,Form_L20!$B$5:$B$52,0))*0.6+INDEX(Form_L20!$N$5:$N$52,MATCH(D8,Form_L20!$B$5:$B$52,0))*0.4 -> 1.54
A9: 4 | B9: D | C9: 46185 | D9: United States | E9: Paraguay | F9: =ROUND((INDEX(Form_L20!$R$5:$R$52,MATCH(D9,Form_L20!$B$5:$B$52,0))*40+MIN(2,MAX(-2.5,INDEX(Form_L20!$M$5:$M$52,MATCH(D9,Form_L20!$B$5:$B$52,0))-INDEX(Form_L20!$N$5:$N$52,MATCH(D9,Form_L20!$B$5:$B$52,0))))*8+MIN(1.3,MAX(-0.7,1.3-INDEX(Form_L20!$N$5:$N$52,MATCH(D9,Form_L20!$B$5:$B$52,0))))*6)*INDEX(Form_L20!$Q$5:$Q$52,MATCH(D9,Form_L20!$B$5:$B$52,0))+INDEX(Tactics!$J$5:$J$52,MATCH(D9,Tactics!$B$5:$B$52,0))*0.3+INDEX(Tactics!$H$5:$H$52,MATCH(D9,Tactics!$B$5:$B$52,0))*1.5,1) -> 55.1 | G9: =ROUND((INDEX(Form_L20!$R$5:$R$52,MATCH(E9,Form_L20!$B$5:$B$52,0))*40+MIN(2,MAX(-2.5,INDEX(Form_L20!$M$5:$M$52,MATCH(E9,Form_L20!$B$5:$B$52,0))-INDEX(Form_L20!$N$5:$N$52,MATCH(E9,Form_L20!$B$5:$B$52,0))))*8+MIN(1.3,MAX(-0.7,1.3-INDEX(Form_L20!$N$5:$N$52,MATCH(E9,Form_L20!$B$5:$B$52,0))))*6)*INDEX(Form_L20!$Q$5:$Q$52,MATCH(E9,Form_L20!$B$5:$B$52,0))+INDEX(Tactics!$J$5:$J$52,MATCH(E9,Tactics!$B$5:$B$52,0))*0.3+INDEX(Tactics!$H$5:$H$52,MATCH(E9,Tactics!$B$5:$B$52,0))*1.5,1) -> 54.6 | H9: =F9-G9 -> 0.5 | I9: =ROUND((1/(1+10^(-H9/15)))*(1-J9),3) -> 0.234 | J9: =ROUND(MAX(0.19,0.56-ABS(H9)/48),3) -> 0.55 | K9: =ROUND(1-I9-J9,3) -> 0.216 | L9: =IF(AND(J9>=I9,J9>=K9),MAX(0,ROUND((AC9+AD9)/2,0))&" - "&MAX(0,ROUND((AC9+AD9)/2,0)),IF(I9>=K9,MAX(ROUND(AC9+0.35,0),MAX(0,ROUND(AD9-0.15,0))+1)&" - "&MAX(0,ROUND(AD9-0.15,0)),MAX(0,ROUND(AC9-0.15,0))&" - "&MAX(ROUND(AD9+0.35,0),MAX(0,ROUND(AC9-0.15,0))+1))) -> 1 - 1 | M9: =IF(AND(J9>=I9,J9>=K9),"Draw",IF(I9>=K9,D9&" win",E9&" win")) -> Draw | N9: =MAX(I9,J9,K9) -> 0.55 | S9: =IF(OR(Q9="",R9=""),"",IF(Q9>R9,D9&" win",IF(R9>Q9,E9&" win","Draw"))) | T9: =IF(U9="","",CHOOSE(MATCH(U9,{0,5,7,8,9,15},0),"Errou","Apenas Vencedor","Vencedor+Gols","Empate","Vencedor+Saldo","CRAVADA")) | U9: =IF(OR(Q9="",R9=""),"",IF(AND(AA9=Q9,AB9=R9),15,IF(AND(AA9=AB9,Q9=R9),8,IF(AND(AA9>AB9,Q9>R9),IF((AA9-AB9)=(Q9-R9),9,IF(AA9=Q9,7,5)),IF(AND(AA9<AB9,Q9<R9),IF((AB9-AA9)=(R9-Q9),9,IF(AB9=R9,7,5)),0))))) | W9: Vencedor+Saldo (9) | Y9: =COUNTIF(U6:U77,9) -> 1 | AA9: =IFERROR(VALUE(LEFT(L9,FIND(" - ",L9)-1)),"") -> 1 | AB9: =IFERROR(VALUE(MID(L9,FIND(" - ",L9)+3,10)),"") -> 1 | AC9: =INDEX(Form_L20!$M$5:$M$52,MATCH(D9,Form_L20!$B$5:$B$52,0))*0.6+INDEX(Form_L20!$N$5:$N$52,MATCH(E9,Form_L20!$B$5:$B$52,0))*0.4 -> 1.3142857 | AD9: =INDEX(Form_L20!$M$5:$M$52,MATCH(E9,Form_L20!$B$5:$B$52,0))*0.6+INDEX(Form_L20!$N$5:$N$52,MATCH(D9,Form_L20!$B$5:$B$52,0))*0.4 -> 1.0380952
A10: 5 | B10: C | C10: 46186 | D10: Brazil | E10: Morocco | F10: =ROUND((INDEX(Form_L20!$R$5:$R$52,MATCH(D10,Form_L20!$B$5:$B$52,0))*40+MIN(2,MAX(-2.5,INDEX(Form_L20!$M$5:$M$52,MATCH(D10,Form_L20!$B$5:$B$52,0))-INDEX(Form_L20!$N$5:$N$52,MATCH(D10,Form_L20!$B$5:$B$52,0))))*8+MIN(1.3,MAX(-0.7,1.3-INDEX(Form_L20!$N$5:$N$52,MATCH(D10,Form_L20!$B$5:$B$52,0))))*6)*INDEX(Form_L20!$Q$5:$Q$52,MATCH(D10,Form_L20!$B$5:$B$52,0))+INDEX(Tactics!$J$5:$J$52,MATCH(D10,Tactics!$B$5:$B$52,0))*0.3+INDEX(Tactics!$H$5:$H$52,MATCH(D10,Tactics!$B$5:$B$52,0))*1.5,1) -> 77.2 | G10: =ROUND((INDEX(Form_L20!$R$5:$R$52,MATCH(E10,Form_L20!$B$5:$B$52,0))*40+MIN(2,MAX(-2.5,INDEX(Form_L20!$M$5:$M$52,MATCH(E10,Form_L20!$B$5:$B$52,0))-INDEX(Form_L20!$N$5:$N$52,MATCH(E10,Form_L20!$B$5:$B$52,0))))*8+MIN(1.3,MAX(-0.7,1.3-INDEX(Form_L20!$N$5:$N$52,MATCH(E10,Form_L20!$B$5:$B$52,0))))*6)*INDEX(Form_L20!$Q$5:$Q$52,MATCH(E10,Form_L20!$B$5:$B$52,0))+INDEX(Tactics!$J$5:$J$52,MATCH(E10,Tactics!$B$5:$B$52,0))*0.3+INDEX(Tactics!$H$5:$H$52,MATCH(E10,Tactics!$B$5:$B$52,0))*1.5,1) -> 72.3 | H10: =F10-G10 -> 4.9 | I10: =ROUND((1/(1+10^(-H10/15)))*(1-J10),3) -> 0.368 | J10: =ROUND(MAX(0.19,0.56-ABS(H10)/48),3) -> 0.458 | K10: =ROUND(1-I10-J10,3) -> 0.174 | L10: =IF(AND(J10>=I10,J10>=K10),MAX(0,ROUND((AC10+AD10)/2,0))&" - "&MAX(0,ROUND((AC10+AD10)/2,0)),IF(I10>=K10,MAX(ROUND(AC10+0.35,0),MAX(0,ROUND(AD10-0.15,0))+1)&" - "&MAX(0,ROUND(AD10-0.15,0)),MAX(0,ROUND(AC10-0.15,0))&" - "&MAX(ROUND(AD10+0.35,0),MAX(0,ROUND(AC10-0.15,0))+1))) -> 1 - 1 | M10: =IF(AND(J10>=I10,J10>=K10),"Draw",IF(I10>=K10,D10&" win",E10&" win")) -> Draw | N10: =MAX(I10,J10,K10) -> 0.458 | S10: =IF(OR(Q10="",R10=""),"",IF(Q10>R10,D10&" win",IF(R10>Q10,E10&" win","Draw"))) | T10: =IF(U10="","",CHOOSE(MATCH(U10,{0,5,7,8,9,15},0),"Errou","Apenas Vencedor","Vencedor+Gols","Empate","Vencedor+Saldo","CRAVADA")) | U10: =IF(OR(Q10="",R10=""),"",IF(AND(AA10=Q10,AB10=R10),15,IF(AND(AA10=AB10,Q10=R10),8,IF(AND(AA10>AB10,Q10>R10),IF((AA10-AB10)=(Q10-R10),9,IF(AA10=Q10,7,5)),IF(AND(AA10<AB10,Q10<R10),IF((AB10-AA10)=(R10-Q10),9,IF(AB10=R10,7,5)),0))))) | W10: Empates (8) | Y10: =COUNTIF(U6:U77,8) -> 0 | AA10: =IFERROR(VALUE(LEFT(L10,FIND(" - ",L10)-1)),"") -> 1 | AB10: =IFERROR(VALUE(MID(L10,FIND(" - ",L10)+3,10)),"") -> 1 | AC10: =INDEX(Form_L20!$M$5:$M$52,MATCH(D10,Form_L20!$B$5:$B$52,0))*0.6+INDEX(Form_L20!$N$5:$N$52,MATCH(E10,Form_L20!$B$5:$B$52,0))*0.4 -> 1.42 | AD10: =INDEX(Form_L20!$M$5:$M$52,MATCH(E10,Form_L20!$B$5:$B$52,0))*0.6+INDEX(Form_L20!$N$5:$N$52,MATCH(D10,Form_L20!$B$5:$B$52,0))*0.4 -> 1.29
A11: 6 | B11: D | C11: 46186 | D11: Australia | E11: Türkiye | F11: =ROUND((INDEX(Form_L20!$R$5:$R$52,MATCH(D11,Form_L20!$B$5:$B$52,0))*40+MIN(2,MAX(-2.5,INDEX(Form_L20!$M$5:$M$52,MATCH(D11,Form_L20!$B$5:$B$52,0))-INDEX(Form_L20!$N$5:$N$52,MATCH(D11,Form_L20!$B$5:$B$52,0))))*8+MIN(1.3,MAX(-0.7,1.3-INDEX(Form_L20!$N$5:$N$52,MATCH(D11,Form_L20!$B$5:$B$52,0))))*6)*INDEX(Form_L20!$Q$5:$Q$52,MATCH(D11,Form_L20!$B$5:$B$52,0))+INDEX(Tactics!$J$5:$J$52,MATCH(D11,Tactics!$B$5:$B$52,0))*0.3+INDEX(Tactics!$H$5:$H$52,MATCH(D11,Tactics!$B$5:$B$52,0))*1.5,1) -> 58 | G11: =ROUND((INDEX(Form_L20!$R$5:$R$52,MATCH(E11,Form_L20!$B$5:$B$52,0))*40+MIN(2,MAX(-2.5,INDEX(Form_L20!$M$5:$M$52,MATCH(E11,Form_L20!$B$5:$B$52,0))-INDEX(Form_L20!$N$5:$N$52,MATCH(E11,Form_L20!$B$5:$B$52,0))))*8+MIN(1.3,MAX(-0.7,1.3-INDEX(Form_L20!$N$5:$N$52,MATCH(E11,Form_L20!$B$5:$B$52,0))))*6)*INDEX(Form_L20!$Q$5:$Q$52,MATCH(E11,Form_L20!$B$5:$B$52,0))+INDEX(Tactics!$J$5:$J$52,MATCH(E11,Tactics!$B$5:$B$52,0))*0.3+INDEX(Tactics!$H$5:$H$52,MATCH(E11,Tactics!$B$5:$B$52,0))*1.5,1) -> 71.1 | H11: =F11-G11 -> -13.1 | I11: =ROUND((1/(1+10^(-H11/15)))*(1-J11),3) -> 0.084 | J11: =ROUND(MAX(0.19,0.56-ABS(H11)/48),3) -> 0.287 | K11: =ROUND(1-I11-J11,3) -> 0.629 | L11: =IF(AND(J11>=I11,J11>=K11),MAX(0,ROUND((AC11+AD11)/2,0))&" - "&MAX(0,ROUND((AC11+AD11)/2,0)),IF(I11>=K11,MAX(ROUND(AC11+0.35,0),MAX(0,ROUND(AD11-0.15,0))+1)&" - "&MAX(0,ROUND(AD11-0.15,0)),MAX(0,ROUND(AC11-0.15,0))&" - "&MAX(ROUND(AD11+0.35,0),MAX(0,ROUND(AC11-0.15,0))+1))) -> 1 - 2 | M11: =IF(AND(J11>=I11,J11>=K11),"Draw",IF(I11>=K11,D11&" win",E11&" win")) -> Türkiye win | N11: =MAX(I11,J11,K11) -> 0.629 | S11: =IF(OR(Q11="",R11=""),"",IF(Q11>R11,D11&" win",IF(R11>Q11,E11&" win","Draw"))) | T11: =IF(U11="","",CHOOSE(MATCH(U11,{0,5,7,8,9,15},0),"Errou","Apenas Vencedor","Vencedor+Gols","Empate","Vencedor+Saldo","CRAVADA")) | U11: =IF(OR(Q11="",R11=""),"",IF(AND(AA11=Q11,AB11=R11),15,IF(AND(AA11=AB11,Q11=R11),8,IF(AND(AA11>AB11,Q11>R11),IF((AA11-AB11)=(Q11-R11),9,IF(AA11=Q11,7,5)),IF(AND(AA11<AB11,Q11<R11),IF((AB11-AA11)=(R11-Q11),9,IF(AB11=R11,7,5)),0))))) | W11: Vencedor+Gols (7) | Y11: =COUNTIF(U6:U77,7) -> 0 | AA11: =IFERROR(VALUE(LEFT(L11,FIND(" - ",L11)-1)),"") -> 1 | AB11: =IFERROR(VALUE(MID(L11,FIND(" - ",L11)+3,10)),"") -> 2 | AC11: =INDEX(Form_L20!$M$5:$M$52,MATCH(D11,Form_L20!$B$5:$B$52,0))*0.6+INDEX(Form_L20!$N$5:$N$52,MATCH(E11,Form_L20!$B$5:$B$52,0))*0.4 -> 1.62 | AD11: =INDEX(Form_L20!$M$5:$M$52,MATCH(E11,Form_L20!$B$5:$B$52,0))*0.6+INDEX(Form_L20!$N$5:$N$52,MATCH(D11,Form_L20!$B$5:$B$52,0))*0.4 -> 1.745
A12: 7 | B12: C | C12: 46186 | D12: Haiti | E12: Scotland | F12: =ROUND((INDEX(Form_L20!$R$5:$R$52,MATCH(D12,Form_L20!$B$5:$B$52,0))*40+MIN(2,MAX(-2.5,INDEX(Form_L20!$M$5:$M$52,MATCH(D12,Form_L20!$B$5:$B$52,0))-INDEX(Form_L20!$N$5:$N$52,MATCH(D12,Form_L20!$B$5:$B$52,0))))*8+MIN(1.3,MAX(-0.7,1.3-INDEX(Form_L20!$N$5:$N$52,MATCH(D12,Form_L20!$B$5:$B$52,0))))*6)*INDEX(Form_L20!$Q$5:$Q$52,MATCH(D12,Form_L20!$B$5:$B$52,0))+INDEX(Tactics!$J$5:$J$52,MATCH(D12,Tactics!$B$5:$B$52,0))*0.3+INDEX(Tactics!$H$5:$H$52,MATCH(D12,Tactics!$B$5:$B$52,0))*1.5,1) -> 52.7 | G12: =ROUND((INDEX(Form_L20!$R$5:$R$52,MATCH(E12,Form_L20!$B$5:$B$52,0))*40+MIN(2,MAX(-2.5,INDEX(Form_L20!$M$5:$M$52,MATCH(E12,Form_L20!$B$5:$B$52,0))-INDEX(Form_L20!$N$5:$N$52,MATCH(E12,Form_L20!$B$5:$B$52,0))))*8+MIN(1.3,MAX(-0.7,1.3-INDEX(Form_L20!$N$5:$N$52,MATCH(E12,Form_L20!$B$5:$B$52,0))))*6)*INDEX(Form_L20!$Q$5:$Q$52,MATCH(E12,Form_L20!$B$5:$B$52,0))+INDEX(Tactics!$J$5:$J$52,MATCH(E12,Tactics!$B$5:$B$52,0))*0.3+INDEX(Tactics!$H$5:$H$52,MATCH(E12,Tactics!$B$5:$B$52,0))*1.5,1) -> 70.7 | H12: =F12-G12 -> -18 | I12: =ROUND((1/(1+10^(-H12/15)))*(1-J12),3) -> 0.048 | J12: =ROUND(MAX(0.19,0.56-ABS(H12)/48),3) -> 0.19 | K12: =ROUND(1-I12-J12,3) -> 0.762 | L12: =IF(AND(J12>=I12,J12>=K12),MAX(0,ROUND((AC12+AD12)/2,0))&" - "&MAX(0,ROUND((AC12+AD12)/2,0)),IF(I12>=K12,MAX(ROUND(AC12+0.35,0),MAX(0,ROUND(AD12-0.15,0))+1)&" - "&MAX(0,ROUND(AD12-0.15,0)),MAX(0,ROUND(AC12-0.15,0))&" - "&MAX(ROUND(AD12+0.35,0),MAX(0,ROUND(AC12-0.15,0))+1))) -> 1 - 2 | M12: =IF(AND(J12>=I12,J12>=K12),"Draw",IF(I12>=K12,D12&" win",E12&" win")) -> Scotland win | N12: =MAX(I12,J12,K12) -> 0.762 | S12: =IF(OR(Q12="",R12=""),"",IF(Q12>R12,D12&" win",IF(R12>Q12,E12&" win","Draw"))) | T12: =IF(U12="","",CHOOSE(MATCH(U12,{0,5,7,8,9,15},0),"Errou","Apenas Vencedor","Vencedor+Gols","Empate","Vencedor+Saldo","CRAVADA")) | U12: =IF(OR(Q12="",R12=""),"",IF(AND(AA12=Q12,AB12=R12),15,IF(AND(AA12=AB12,Q12=R12),8,IF(AND(AA12>AB12,Q12>R12),IF((AA12-AB12)=(Q12-R12),9,IF(AA12=Q12,7,5)),IF(AND(AA12<AB12,Q12<R12),IF((AB12-AA12)=(R12-Q12),9,IF(AB12=R12,7,5)),0))))) | W12: Apenas Vencedor (5) | Y12: =COUNTIF(U6:U77,5) -> 0 | AA12: =IFERROR(VALUE(LEFT(L12,FIND(" - ",L12)-1)),"") -> 1 | AB12: =IFERROR(VALUE(MID(L12,FIND(" - ",L12)+3,10)),"") -> 2 | AC12: =INDEX(Form_L20!$M$5:$M$52,MATCH(D12,Form_L20!$B$5:$B$52,0))*0.6+INDEX(Form_L20!$N$5:$N$52,MATCH(E12,Form_L20!$B$5:$B$52,0))*0.4 -> 1.3666667 | AD12: =INDEX(Form_L20!$M$5:$M$52,MATCH(E12,Form_L20!$B$5:$B$52,0))*0.6+INDEX(Form_L20!$N$5:$N$52,MATCH(D12,Form_L20!$B$5:$B$52,0))*0.4 -> 1.7
A13: 8 | B13: B | C13: 46186 | D13: Qatar | E13: Switzerland | F13: =ROUND((INDEX(Form_L20!$R$5:$R$52,MATCH(D13,Form_L20!$B$5:$B$52,0))*40+MIN(2,MAX(-2.5,INDEX(Form_L20!$M$5:$M$52,MATCH(D13,Form_L20!$B$5:$B$52,0))-INDEX(Form_L20!$N$5:$N$52,MATCH(D13,Form_L20!$B$5:$B$52,0))))*8+MIN(1.3,MAX(-0.7,1.3-INDEX(Form_L20!$N$5:$N$52,MATCH(D13,Form_L20!$B$5:$B$52,0))))*6)*INDEX(Form_L20!$Q$5:$Q$52,MATCH(D13,Form_L20!$B$5:$B$52,0))+INDEX(Tactics!$J$5:$J$52,MATCH(D13,Tactics!$B$5:$B$52,0))*0.3+INDEX(Tactics!$H$5:$H$52,MATCH(D13,Tactics!$B$5:$B$52,0))*1.5,1) -> 41.7 | G13: =ROUND((INDEX(Form_L20!$R$5:$R$52,MATCH(E13,Form_L20!$B$5:$B$52,0))*40+MIN(2,MAX(-2.5,INDEX(Form_L20!$M$5:$M$52,MATCH(E13,Form_L20!$B$5:$B$52,0))-INDEX(Form_L20!$N$5:$N$52,MATCH(E13,Form_L20!$B$5:$B$52,0))))*8+MIN(1.3,MAX(-0.7,1.3-INDEX(Form_L20!$N$5:$N$52,MATCH(E13,Form_L20!$B$5:$B$52,0))))*6)*INDEX(Form_L20!$Q$5:$Q$52,MATCH(E13,Form_L20!$B$5:$B$52,0))+INDEX(Tactics!$J$5:$J$52,MATCH(E13,Tactics!$B$5:$B$52,0))*0.3+INDEX(Tactics!$H$5:$H$52,MATCH(E13,Tactics!$B$5:$B$52,0))*1.5,1) -> 84.1 | H13: =F13-G13 -> -42.4 | I13: =ROUND((1/(1+10^(-H13/15)))*(1-J13),3) -> 0.001 | J13: =ROUND(MAX(0.19,0.56-ABS(H13)/48),3) -> 0.19 | K13: =ROUND(1-I13-J13,3) -> 0.809 | L13: =IF(AND(J13>=I13,J13>=K13),MAX(0,ROUND((AC13+AD13)/2,0))&" - "&MAX(0,ROUND((AC13+AD13)/2,0)),IF(I13>=K13,MAX(ROUND(AC13+0.35,0),MAX(0,ROUND(AD13-0.15,0))+1)&" - "&MAX(0,ROUND(AD13-0.15,0)),MAX(0,ROUND(AC13-0.15,0))&" - "&MAX(ROUND(AD13+0.35,0),MAX(0,ROUND(AC13-0.15,0))+1))) -> 1 - 2 | M13: =IF(AND(J13>=I13,J13>=K13),"Draw",IF(I13>=K13,D13&" win",E13&" win")) -> Switzerland win | N13: =MAX(I13,J13,K13) -> 0.809 | S13: =IF(OR(Q13="",R13=""),"",IF(Q13>R13,D13&" win",IF(R13>Q13,E13&" win","Draw"))) | T13: =IF(U13="","",CHOOSE(MATCH(U13,{0,5,7,8,9,15},0),"Errou","Apenas Vencedor","Vencedor+Gols","Empate","Vencedor+Saldo","CRAVADA")) | U13: =IF(OR(Q13="",R13=""),"",IF(AND(AA13=Q13,AB13=R13),15,IF(AND(AA13=AB13,Q13=R13),8,IF(AND(AA13>AB13,Q13>R13),IF((AA13-AB13)=(Q13-R13),9,IF(AA13=Q13,7,5)),IF(AND(AA13<AB13,Q13<R13),IF((AB13-AA13)=(R13-Q13),9,IF(AB13=R13,7,5)),0))))) | W13: Zerou (0) | Y13: =COUNTIF(U6:U77,0) -> 1 | AA13: =IFERROR(VALUE(LEFT(L13,FIND(" - ",L13)-1)),"") -> 1 | AB13: =IFERROR(VALUE(MID(L13,FIND(" - ",L13)+3,10)),"") -> 2 | AC13: =INDEX(Form_L20!$M$5:$M$52,MATCH(D13,Form_L20!$B$5:$B$52,0))*0.6+INDEX(Form_L20!$N$5:$N$52,MATCH(E13,Form_L20!$B$5:$B$52,0))*0.4 -> 0.93333333 | AD13: =INDEX(Form_L20!$M$5:$M$52,MATCH(E13,Form_L20!$B$5:$B$52,0))*0.6+INDEX(Form_L20!$N$5:$N$52,MATCH(D13,Form_L20!$B$5:$B$52,0))*0.4 -> 2.1333333
